2025-10-08 15:07:19,302 DEBUG lp_tenant_importer_v2.importers.alert_rules [alert_rules.py:663 _collect_backend_ips] - tenant siems content: {'backends': [NodeRef(id='01925abf82fe0db0a75c190c4316b8a6', name='lb-backend01', ip='10.160.40.202', ip_private='10.41.39.1'), NodeRef(id='01925abf82fe0db0a75c190c4316b8b7', name='lb-backend02', ip='10.160.40.203', ip_private='10.216.206.1')], 'search_heads': [NodeRef(id='19fc63880b018d978aabe9162b851a9d', name='sh01', ip='10.160.40.200', ip_private='')], 'all_in_one': []}
2025-10-08 15:07:19,302 DEBUG lp_tenant_importer_v2.importers.alert_rules [alert_rules.py:671 _collect_backend_ips] - siems private IPs list: ['10.41.39.1', '10.216.206.1']
2025-10-08 15:07:19,303 INFO lp_tenant_importer_v2.core.director_client [director_client.py:684 fetch_resource] - FETCH[4aecae14] POST configapi/2bc98ce16a6d4c4c82e362bc11691488/19fc63880b018d978aabe9162b851a9d/MitreAttacks/fetch pool=2bc98ce16a6d4c4c82e362bc11691488 node=19fc63880b018d978aabe9162b851a9d resource=MitreAttacks/fetch
2025-10-08 15:07:19,303 DEBUG lp_tenant_importer_v2.core.director_client [director_client.py:688 fetch_resource] - FETCH[4aecae14] payload={"data": {}}
2025-10-08 15:07:19,308 DEBUG urllib3.connectionpool [connectionpool.py:1049 _new_conn] - Starting new HTTPS connection (1): 10.160.144.185:443
2025-10-08 15:07:40,362 ERROR lp_tenant_importer_v2.core.director_client [director_client.py:147 _req] - HTTP POST https://10.160.144.185/configapi/2bc98ce16a6d4c4c82e362bc11691488/19fc63880b018d978aabe9162b851a9d/MitreAttacks/fetch failed: HTTPSConnectionPool(host='10.160.144.185', port=443): Max retries exceeded with url: /configapi/2bc98ce16a6d4c4c82e362bc11691488/19fc63880b018d978aabe9162b851a9d/MitreAttacks/fetch (Caused by ConnectTimeoutError(<urllib3.connection.HTTPSConnection object at 0x0000026DA58DBE00>, 'Connection to 10.160.144.185 timed out. (connect timeout=60)'))
2025-10-08 15:07:40,364 WARNING lp_tenant_importer_v2.importers.alert_rules [alert_rules.py:320 _load_mitre_attacks] - Failed fetching MITRE attacks catalog (pool=2bc98ce16a6d4c4c82e362bc11691488): HTTPSConnectionPool(host='10.160.144.185', port=443): Max retries exceeded with url: /configapi/2bc98ce16a6d4c4c82e362bc11691488/19fc63880b018d978aabe9162b851a9d/MitreAttacks/fetch (Caused by ConnectTimeoutError(<urllib3.connection.HTTPSConnection object at 0x0000026DA58DBE00>, 'Connection to 10.160.144.185 timed out. (connect timeout=60)'))
2025-10-08 15:07:40,364 DEBUG lp_tenant_importer_v2.importers.alert_rules [alert_rules.py:323 _load_mitre_attacks] - MITRE cache loaded: pool=2bc98ce16a6d4c4c82e362bc11691488 size=0
2025-10-08 15:07:40,365 INFO lp_tenant_importer_v2.core.director_client [director_client.py:684 fetch_resource] - FETCH[bbc4e00b] POST configapi/2bc98ce16a6d4c4c82e362bc11691488/19fc63880b018d978aabe9162b851a9d/AlertRules/MyAlertRules/fetch pool=2bc98ce16a6d4c4c82e362bc11691488 node=19fc63880b018d978aabe9162b851a9d resource=AlertRules/MyAlertRules/fetch
2025-10-08 15:07:40,366 DEBUG lp_tenant_importer_v2.core.director_client [director_client.py:688 fetch_resource] - FETCH[bbc4e00b] payload={"data": {}}
2025-10-08 15:07:40,368 DEBUG urllib3.connectionpool [connectionpool.py:1049 _new_conn] - Starting new HTTPS connection (2): 10.160.144.185:443
